Workbook

Sheet Guide
A1: 📖 Zakat-LogBook v3.0 — WORKBOOK GUIDE & REFERENCE
A2: Everything you need to know about using this Zakat LogBook. All colour codes, column explanations, and FAQ consolidated here.
A4: 🎨 Colour Coding Standard
B5: Blue text | D5: Manual input cells — these are the cells you type into
B6: Green text | D6: Auto-calculated or linked from another sheet — do not edit
B7: Red text | D7: Debts, liabilities, or amounts still owed
B8: Purple text | D8: Report totals in the Reports sheet
B9: Orange text | D9: Qurbani and certain breakdown values
B10: Yellow background | D10: The person-selector cell on the Reports sheet
B11: Gold background | D11: Nisab threshold — highlights the minimum wealth threshold column
B12: Orange background | D12: Zakat Due column — what you owe for each year
B13: Pink / red bg | D13: Running balance — how much Zakat is still outstanding
A15: 📋 Sheet-by-Sheet Guide
B16: Zakat Summary | D16: Main dashboard. One row per Zakat year. Enter the date, gold price, and oz of gold you own. Everything else is pulled automatically — Stocks, Cash, Debts, Paid amounts, Status, and Hawl countdown.
B17: Stocks | D17: Track your investment and brokerage accounts. One row per year. Each column = one account. Insert a new column before 'Total Portfolio' to add more accounts.
B18: Cash | D18: Track cash, checking, savings, and liquid accounts. Same row-per-year layout. Insert columns before 'Total Cash' to add more accounts.
B19: Debts | D19: List all outstanding debts. Totals are deducted from your zakatable assets in the Summary. Insert columns before 'Total Debts' to add more debt types.
B20: Ledger | D20: Record every payment — Zakat, Sadaqah, Fitrana, Qurbani, and other types. Use the Type, Service, and Given To dropdowns. Amount + Fees = Total Paid. Running Total auto-cumulates.
B21: Reports | D21: Select any person from the dropdown to see all payments made to them, broken down by type, with full transaction history and service fee summary. Filter by year with the C5 dropdown.
B22: Settings | D22: Manage your dropdown lists — Payment Types (col B), Transfer Services (col D), Recipients (col F). Configure Nisab oz values and use the live Nisab calculator. All changes take effect immediately.
B23: Guide (this) | D23: Reference sheet. All colour codes, column explanations, and FAQ. Nothing here affects any calculations.
A25: 📊 Zakat Summary — Column-by-Column Explanation
B26: Zakat Date | D26: The date on which you calculate your annual Zakat. Typically the same date each lunar year (your 'Zakat anniversary'). Enter this first — other columns reference it.
B27: Stock Portfolio ($) | D27: Auto-pulled from the Stocks sheet — total of all brokerage/investment accounts for that row. Make sure the Stocks row matches this Zakat year.
B28: Cash & Liquid ($) | D28: Auto-pulled from the Cash sheet — total of all checking, savings, and liquid balances for that row.
B29: Total Debts ($) | D29: Auto-pulled from the Debts sheet — subtracted from your assets when calculating net zakatable wealth.
B30: Gold Price ($/oz) | D30: Enter the gold spot price in USD per troy oz on your Zakat date. Look up at goldprice.org or kitco.com. This also drives the Nisab threshold.
B31: Gold Owned (oz) | D31: How many troy oz of gold you personally own on that date (jewelry, coins, bars, etc.).
B32: Value of Gold ($) | D32: Auto-calculated: Gold Price × Gold Owned oz.
B33: Net Zakatable Assets ($) | D33: Stocks + Cash + Gold Value − Debts. This is the total wealth on which Zakat is assessed.
B34: Nisab Threshold ($) | D34: The minimum wealth threshold for Zakat to be obligatory. Calculated as: Gold Price × Nisab oz (default 2.7315 oz = 85g gold). Edit the oz value in Settings D44. If Net Assets < Nisab, no Zakat is due.
B35: Zakat Due (2.5%) ($) | D35: 2.5% of Net Zakatable Assets — but ONLY if Net Assets ≥ Nisab. Shows $0 if below threshold. Zakat is on your FULL net wealth, not just the surplus above Nisab.
B36: Paid This Period ($) | D36: Auto-calculated from the Ledger: total of all 'Zakat' type payments with dates between the previous Zakat date and this one.
B37: Running Balance ($) | D37: Cumulative: Zakat Due − Paid This Period + previous year's balance. Positive = you still owe. Negative = you have overpaid (credit carries forward).
... B39: Brought Forward ($) | D39: The unpaid Zakat balance carried in from the prior year. Read-only. Highlighted red if > 0 to remind you there is outstanding Zakat from a previous year.
A41: 🌙 What Is Nisab? — Detailed Explanation
B42: Definition | D42: Nisab (نصاب) is the minimum amount of wealth a Muslim must possess continuously for one lunar year before Zakat becomes obligatory. If your net zakatable assets fall below Nisab at any point, the Hawl (year cycle) resets.
B43: Gold Standard (default) | D43: 85 grams of gold. Divide 85 by 31.1035 (grams per troy oz) = 2.7315 troy oz. Multiply by the current gold spot price to get the Nisab in dollars. This is the default used in Zakat Summary. The 2.7315 value is stored in Settings D44.
B44: Silver Standard | D44: 595 grams of silver = 19.1358 troy oz × silver price. Because silver is much cheaper, the silver Nisab threshold is significantly lower — meaning more people qualify. Stored in Settings D45.
B45: Which should I use? | D45: Follow the guidance of your scholar or local mosque. The gold standard is most widely used in North America and by the four major Sunni schools. Change the Nisab oz in Settings D44 at any time — all calculations update immediately.
...

Sheet Settings
A1: ⚙ Zakat-LogBook v3.0 — SETTINGS
A2: Add or remove items in the lists below. Changes take effect immediately in all dropdown menus.
B3: PAYMENT TYPES | D3: SERVICES / TRANSFER METHODS | F3: RECIPIENTS / GIVEN TO | H3: COLOUR LEGEND
B4: Type Name | D4: Service Name | F4: Recipient Name | H4: Description
B5: Zakat | D5: Remitly | F5: Islamic Relief USA | H5: Blue text: Manual input cells — type here
B6: Sadaqah | D6: Western Union | F6: Zakat Foundation | H6: Green text: Calculated / linked from another sheet
B7: Fitrana | D7: Wise (TransferWise) | F7: LaunchGood | H7: Red text: Debts or amounts owed
B8: Qurbani | D8: PayPal | F8: Local Mosque | H8: Purple text: Report totals
D9: Zelle | F9: Family Member | H9: Gold background: Nisab-related cells
D10: Bank Transfer | H10: Orange background: Zakat due amounts
D11: Cash
D12: Check
D13: Venmo
D14: CashApp
D15: MoneyGram
D16: Other
B35: ← Add more types above | D35: ← Add more services above | F35: ← Add recipients above
A37: NISAB SETTINGS
B38: What is Nisab? | C38: Nisab is the minimum threshold of wealth a Muslim must possess for one full lunar year before Zakat becomes obligatory. If your net zakatable assets are below Nisab on your Zakat date, no Zakat is due. Once above it, 2.5% of your FULL net wealth is owed.
B39: Two standards: | C39: Scholars use two measures: (1) Gold Nisab = 85 grams of gold. (2) Silver Nisab = 595 grams of silver. Gold (85g) is the most widely used standard today. Silver gives a lower threshold.
B40: How it's calculated: | C40: Gold Nisab = 85g ÷ 31.1035g per troy oz = 2.7315 troy oz × current gold price. Example: if gold = $3,000/oz then Nisab = 2.7315 × $3,000 = $8,194.50. The oz values are stored in cells D44 and D45 below — edit them if your scholar uses different values.
B42: Setting | D42: Your Value | F42: Notes
B43: Nisab Standard | D43: Gold | F43: Gold (85g) or Silver (595g) — Gold is the default used in Zakat Summary
B44: Gold Nisab (troy oz) | D44: 2.7315 | F44: 85g ÷ 31.1035 g/oz = 2.7315 oz | Change if your scholar uses a different value
B45: Silver Nisab (troy oz) | D45: 19.1358 | F45: 595g ÷ 31.1035 g/oz = 19.1358 oz | Only relevant if switching to silver standard
A47: ⚡ CURRENT NISAB CALCULATOR — Enter today's gold price to see threshold instantly
B48: Today's Gold Price ($/oz) | D48: Gold Nisab Today ($) | F48: Silver Price ($/oz) — optional
B49: 0 | D49: =IF(B49=0,"Enter price →",B49*$D$44) -> Enter price → | F49: 0
D50: =IF(B49=0,"","Silver Nisab = "&TEXT(F49*$D$45,"$#,##0.00"))

Sheet Zakat Summary
A1: Zakat-LogBook v3.0 — ANNUAL ZAKAT SUMMARY
A2: One row per Zakat year. Enter the date in col A — Stocks, Cash, and Debts pull automatically from their sheets. Enter gold price + oz. All other cells calculate automatically.
A3: Zakat Date | B3: Stock Portfolio ($) | C3: Cash & Liquid ($) | D3: Total Debts ($) | E3: Gold Price ($/oz) | F3: Gold Owned (oz) | G3: Value of Gold ($) | H3: Net Zakatable Assets ($) | I3: Nisab Threshold ($) | J3: Zakat Due (2.5%) ($) | K3: Paid This Period ($) | L3: Running Balance ($) | M3: Status | N3: Brought Forward ($)
A4: Enter your Zakat calculation date | B4: Auto-pulled from Stocks sheet total for matching date | C4: Auto-pulled from Cash sheet total for matching date | D4: Auto-pulled from Debts sheet total for matching date | E4: Enter gold spot price on this date ($ per troy oz) | F4: Enter how many troy oz of gold you own | G4: Gold Value = Gold Price × oz (auto-calculated) | H4: Net Assets = Stocks + Cash + Gold − Debts | I4: Nisab = Gold Price × 2.7315 oz (= 85g). Edit the oz value in Settings D44. Zakat is ONLY due if Net Assets ≥ Nisab. | J4: 2.5% of Net Assets if ≥ Nisab, else $0. Zakat is on your FULL net wealth, not just the surplus above Nisab. | K4: Zakat payments pulled automatically from Ledger entries within this Zakat period | L4: Cumulative balance: positive = still owed, zero or negative = fully paid | M4: Auto status: ✅ Paid in Full / ⚠️ Partially Paid / ❌ Not Started | N4: Unpaid Zakat balance carried forward from the prior year (read-only)
B5: =IFERROR(INDEX(Stocks!$1:$1048576,4,MATCH("Total Portfolio",Stocks!$3:$3,0)),0) -> 0 | C5: =IFERROR(INDEX(Cash!$1:$1048576,4,MATCH("Total Cash",Cash!$3:$3,0)),0) -> 0 | D5: =IFERROR(INDEX(Debts!$1:$1048576,4,MATCH("Total Debts",Debts!$3:$3,0)),0) -> 0 | G5: =E5*F5 -> 0 | H5: =B5+C5+G5-D5 -> 0 | I5: =E5*Settings!$D$44 -> 0 | J5: =IF(H5>=I5,H5*0.025,0) -> 0 | K5: =IF(A5="","",SUMIFS(Ledger!H$6:H$205,Ledger!B$6:B$205,"Zakat",Ledger!A$6:A$205,"<="&A5)) | L5: =IF(J5=0,"",J5-IF(K5="",0,K5)) | M5: =IF(J5=0,"",IF(L5<=0,"✅ Paid in Full",IF(K5=0,"❌ Not Started","⚠️ Partially Paid"))) | N5: =IF(A5="","",0)
B6: =IFERROR(INDEX(Stocks!$1:$1048576,5,MATCH("Total Portfolio",Stocks!$3:$3,0)),0) -> 0 | C6: =IFERROR(INDEX(Cash!$1:$1048576,5,MATCH("Total Cash",Cash!$3:$3,0)),0) -> 0 | D6: =IFERROR(INDEX(Debts!$1:$1048576,5,MATCH("Total Debts",Debts!$3:$3,0)),0) -> 0 | G6: =E6*F6 -> 0 | H6: =B6+C6+G6-D6 -> 0 | I6: =E6*Settings!$D$44 -> 0 | J6: =IF(H6>=I6,H6*0.025,0) -> 0 | K6: =IF(A6="","",SUMIFS(Ledger!H$6:H$205,Ledger!B$6:B$205,"Zakat",Ledger!A$6:A$205,">"&A5,Ledger!A$6:A$205,"<="&A6)) | L6: =IF(J6=0,"",J6-IF(K6="",0,K6)+IF(L5="",0,L5)) | M6: =IF(J6=0,"",IF(L6<=0,"✅ Paid in Full",IF(K6=0,"❌ Not Started","⚠️ Partially Paid"))) | N6: =IF(A6="","",IF(L5="",0,MAX(0,L5)))
B7: =IFERROR(INDEX(Stocks!$1:$1048576,6,MATCH("Total Portfolio",Stocks!$3:$3,0)),0) -> 0 | C7: =IFERROR(INDEX(Cash!$1:$1048576,6,MATCH("Total Cash",Cash!$3:$3,0)),0) -> 0 | D7: =IFERROR(INDEX(Debts!$1:$1048576,6,MATCH("Total Debts",Debts!$3:$3,0)),0) -> 0 | G7: =E7*F7 -> 0 | H7: =B7+C7+G7-D7 -> 0 | I7: =E7*Settings!$D$44 -> 0 | J7: =IF(H7>=I7,H7*0.025,0) -> 0 | K7: =IF(A7="","",SUMIFS(Ledger!H$6:H$205,Ledger!B$6:B$205,"Zakat",Ledger!A$6:A$205,">"&A6,Ledger!A$6:A$205,"<="&A7)) | L7: =IF(J7=0,"",J7-IF(K7="",0,K7)+IF(L6="",0,L6)) | M7: =IF(J7=0,"",IF(L7<=0,"✅ Paid in Full",IF(K7=0,"❌ Not Started","⚠️ Partially Paid"))) | N7: =IF(A7="","",IF(L6="",0,MAX(0,L6)))
B8: =IFERROR(INDEX(Stocks!$1:$1048576,7,MATCH("Total Portfolio",Stocks!$3:$3,0)),0) -> 0 | C8: =IFERROR(INDEX(Cash!$1:$1048576,7,MATCH("Total Cash",Cash!$3:$3,0)),0) -> 0 | D8: =IFERROR(INDEX(Debts!$1:$1048576,7,MATCH("Total Debts",Debts!$3:$3,0)),0) -> 0 | G8: =E8*F8 -> 0 | H8: =B8+C8+G8-D8 -> 0 | I8: =E8*Settings!$D$44 -> 0 | J8: =IF(H8>=I8,H8*0.025,0) -> 0 | K8: =IF(A8="","",SUMIFS(Ledger!H$6:H$205,Ledger!B$6:B$205,"Zakat",Ledger!A$6:A$205,">"&A7,Ledger!A$6:A$205,"<="&A8)) | L8: =IF(J8=0,"",J8-IF(K8="",0,K8)+IF(L7="",0,L7)) | M8: =IF(J8=0,"",IF(L8<=0,"✅ Paid in Full",IF(K8=0,"❌ Not Started","⚠️ Partially Paid"))) | N8: =IF(A8="","",IF(L7="",0,MAX(0,L7)))
B9: =IFERROR(INDEX(Stocks!$1:$1048576,8,MATCH("Total Portfolio",Stocks!$3:$3,0)),0) -> 0 | C9: =IFERROR(INDEX(Cash!$1:$1048576,8,MATCH("Total Cash",Cash!$3:$3,0)),0) -> 0 | D9: =IFERROR(INDEX(Debts!$1:$1048576,8,MATCH("Total Debts",Debts!$3:$3,0)),0) -> 0 | G9: =E9*F9 -> 0 | H9: =B9+C9+G9-D9 -> 0 | I9: =E9*Settings!$D$44 -> 0 | J9: =IF(H9>=I9,H9*0.025,0) -> 0 | K9: =IF(A9="","",SUMIFS(Ledger!H$6:H$205,Ledger!B$6:B$205,"Zakat",Ledger!A$6:A$205,">"&A8,Ledger!A$6:A$205,"<="&A9)) | L9: =IF(J9=0,"",J9-IF(K9="",0,K9)+IF(L8="",0,L8)) | M9: =IF(J9=0,"",IF(L9<=0,"✅ Paid in Full",IF(K9=0,"❌ Not Started","⚠️ Partially Paid"))) | N9: =IF(A9="","",IF(L8="",0,MAX(0,L8)))
B10: =IFERROR(INDEX(Stocks!$1:$1048576,9,MATCH("Total Portfolio",Stocks!$3:$3,0)),0) -> 0 | C10: =IFERROR(INDEX(Cash!$1:$1048576,9,MATCH("Total Cash",Cash!$3:$3,0)),0) -> 0 | D10: =IFERROR(INDEX(Debts!$1:$1048576,9,MATCH("Total Debts",Debts!$3:$3,0)),0) -> 0 | G10: =E10*F10 -> 0 | H10: =B10+C10+G10-D10 -> 0 | I10: =E10*Settings!$D$44 -> 0 | J10: =IF(H10>=I10,H10*0.025,0) -> 0 | K10: =IF(A10="","",SUMIFS(Ledger!H$6:H$205,Ledger!B$6:B$205,"Zakat",Ledger!A$6:A$205,">"&A9,Ledger!A$6:A$205,"<="&A10)) | L10: =IF(J10=0,"",J10-IF(K10="",0,K10)+IF(L9="",0,L9)) | M10: =IF(J10=0,"",IF(L10<=0,"✅ Paid in Full",IF(K10=0,"❌ Not Started","⚠️ Partially Paid"))) | N10: =IF(A10="","",IF(L9="",0,MAX(0,L9)))
B11: =IFERROR(INDEX(Stocks!$1:$1048576,10,MATCH("Total Portfolio",Stocks!$3:$3,0)),0) -> 0 | C11: =IFERROR(INDEX(Cash!$1:$1048576,10,MATCH("Total Cash",Cash!$3:$3,0)),0) -> 0 | D11: =IFERROR(INDEX(Debts!$1:$1048576,10,MATCH("Total Debts",Debts!$3:$3,0)),0) -> 0 | G11: =E11*F11 -> 0 | H11: =B11+C11+G11-D11 -> 0 | I11: =E11*Settings!$D$44 -> 0 | J11: =IF(H11>=I11,H11*0.025,0) -> 0 | K11: =IF(A11="","",SUMIFS(Ledger!H$6:H$205,Ledger!B$6:B$205,"Zakat",Ledger!A$6:A$205,">"&A10,Ledger!A$6:A$205,"<="&A11)) | L11: =IF(J11=0,"",J11-IF(K11="",0,K11)+IF(L10="",0,L10)) | M11: =IF(J11=0,"",IF(L11<=0,"✅ Paid in Full",IF(K11=0,"❌ Not Started","⚠️ Partially Paid"))) | N11: =IF(A11="","",IF(L10="",0,MAX(0,L10)))
B12: =IFERROR(INDEX(Stocks!$1:$1048576,11,MATCH("Total Portfolio",Stocks!$3:$3,0)),0) -> 0 | C12: =IFERROR(INDEX(Cash!$1:$1048576,11,MATCH("Total Cash",Cash!$3:$3,0)),0) -> 0 | D12: =IFERROR(INDEX(Debts!$1:$1048576,11,MATCH("Total Debts",Debts!$3:$3,0)),0) -> 0 | G12: =E12*F12 -> 0 | H12: =B12+C12+G12-D12 -> 0 | I12: =E12*Settings!$D$44 -> 0 | J12: =IF(H12>=I12,H12*0.025,0) -> 0 | K12: =IF(A12="","",SUMIFS(Ledger!H$6:H$205,Ledger!B$6:B$205,"Zakat",Ledger!A$6:A$205,">"&A11,Ledger!A$6:A$205,"<="&A12)) | L12: =IF(J12=0,"",J12-IF(K12="",0,K12)+IF(L11="",0,L11)) | M12: =IF(J12=0,"",IF(L12<=0,"✅ Paid in Full",IF(K12=0,"❌ Not Started","⚠️ Partially Paid"))) | N12: =IF(A12="","",IF(L11="",0,MAX(0,L11)))
B13: =IFERROR(INDEX(Stocks!$1:$1048576,12,MATCH("Total Portfolio",Stocks!$3:$3,0)),0) -> 0 | C13: =IFERROR(INDEX(Cash!$1:$1048576,12,MATCH("Total Cash",Cash!$3:$3,0)),0) -> 0 | D13: =IFERROR(INDEX(Debts!$1:$1048576,12,MATCH("Total Debts",Debts!$3:$3,0)),0) -> 0 | G13: =E13*F13 -> 0 | H13: =B13+C13+G13-D13 -> 0 | I13: =E13*Settings!$D$44 -> 0 | J13: =IF(H13>=I13,H13*0.025,0) -> 0 | K13: =IF(A13="","",SUMIFS(Ledger!H$6:H$205,Ledger!B$6:B$205,"Zakat",Ledger!A$6:A$205,">"&A12,Ledger!A$6:A$205,"<="&A13)) | L13: =IF(J13=0,"",J13-IF(K13="",0,K13)+IF(L12="",0,L12)) | M13: =IF(J13=0,"",IF(L13<=0,"✅ Paid in Full",IF(K13=0,"❌ Not Started","⚠️ Partially Paid"))) | N13: =IF(A13="","",IF(L12="",0,MAX(0,L12)))
B14: =IFERROR(INDEX(Stocks!$1:$1048576,13,MATCH("Total Portfolio",Stocks!$3:$3,0)),0) -> 0 | C14: =IFERROR(INDEX(Cash!$1:$1048576,13,MATCH("Total Cash",Cash!$3:$3,0)),0) -> 0 | D14: =IFERROR(INDEX(Debts!$1:$1048576,13,MATCH("Total Debts",Debts!$3:$3,0)),0) -> 0 | G14: =E14*F14 -> 0 | H14: =B14+C14+G14-D14 -> 0 | I14: =E14*Settings!$D$44 -> 0 | J14: =IF(H14>=I14,H14*0.025,0) -> 0 | K14: =IF(A14="","",SUMIFS(Ledger!H$6:H$205,Ledger!B$6:B$205,"Zakat",Ledger!A$6:A$205,">"&A13,Ledger!A$6:A$205,"<="&A14)) | L14: =IF(J14=0,"",J14-IF(K14="",0,K14)+IF(L13="",0,L13)) | M14: =IF(J14=0,"",IF(L14<=0,"✅ Paid in Full",IF(K14=0,"❌ Not Started","⚠️ Partially Paid"))) | N14: =IF(A14="","",IF(L13="",0,MAX(0,L13)))
A17: ZAKAT SUMMARY DASHBOARD
A18: Total Zakat Owed (All Years) | C18: Total Zakat Paid (Ledger) | E18: Total Sadaqah Paid (Ledger) | G18: Total Fitrana Paid (Ledger) | I18: Total Qurbani Paid (Ledger) | K18: Outstanding Balance (Zakat Owed − Paid)
A19: =SUMIF(J5:J14,">"&0,J5:J14) -> 0 | C19: =SUMIF(Ledger!B$6:B$205,"Zakat",Ledger!H$6:H$205) -> 0 | E19: =SUMIF(Ledger!B$6:B$205,"Sadaqah",Ledger!H$6:H$205) -> 0 | G19: =SUMIF(Ledger!B$6:B$205,"Fitrana",Ledger!H$6:H$205) -> 0 | I19: =SUMIF(Ledger!B$6:B$205,"Qurbani",Ledger!H$6:H$205) -> 0 | K19: =SUMIF(J5:J14,">"&0,J5:J14)-SUMIF(Ledger!B$6:B$205,"Zakat",Ledger!H$6:H$205) -> 0
A22: 🌙 HAWL TRACKER — Next Zakat Due Date
A23: Hawl = one complete lunar year (354 days) of wealth above Nisab. Countdown updates automatically based on your most recent Zakat date in column A.
A24: Last Zakat Date | C24: Next Due (+354 days) | E24: Days Remaining | G24: Status | J24: Today (auto)
A25: =IF(COUNTA(A5:A14)=0,"No dates yet",MAX(A5:A14)) -> No dates yet | C25: =IF(A25="No dates yet","",A25+354) | E25: =IF(C25="","",MAX(0,C25-TODAY())) | G25: =IF(C25="","",IF(TODAY()>C25,"🕌 Zakat Due Now!",IF(C25-TODAY()<=30,"⚠️ Due Soon (< 30 days)","✅ Hawl in progress"))) | J25: =TODAY() -> 46094

Sheet Stocks
A1: STOCK & INVESTMENT PORTFOLIO
A2: Enter the total value of each account on your Zakat calculation date. Match the date to the Zakat Summary row. Total column auto-sums.
A3: Date | B3: TD Ameritrade | C3: Charles Schwab | D3: Fidelity | E3: Vanguard | F3: Robinhood | G3: Other Account | H3: Total Portfolio
H4: =SUM(B4:G4) -> 0
H5: =SUM(B5:G5) -> 0
H6: =SUM(B6:G6) -> 0
H7: =SUM(B7:G7) -> 0
H8: =SUM(B8:G8) -> 0
H9: =SUM(B9:G9) -> 0
H10: =SUM(B10:G10) -> 0
H11: =SUM(B11:G11) -> 0
H12: =SUM(B12:G12) -> 0
H13: =SUM(B13:G13) -> 0

Sheet Cash
A1: CASH & LIQUID ASSETS
A2: Enter the total balance of each account on your Zakat calculation date. Match the date to the Zakat Summary row. Total column auto-sums.
A3: Date | B3: Chase Checking | C3: Chase Savings | D3: Bank of America | E3: Money Market | F3: Cash on Hand | G3: Other Liquid | H3: Total Cash
H4: =SUM(B4:G4) -> 0
H5: =SUM(B5:G5) -> 0
H6: =SUM(B6:G6) -> 0
H7: =SUM(B7:G7) -> 0
H8: =SUM(B8:G8) -> 0
H9: =SUM(B9:G9) -> 0
H10: =SUM(B10:G10) -> 0
H11: =SUM(B11:G11) -> 0
H12: =SUM(B12:G12) -> 0
H13: =SUM(B13:G13) -> 0

Sheet Debts
A1: OUTSTANDING DEBTS
A2: Enter current balances of debts on your Zakat calculation date. Match the date to the Zakat Summary row. Total column auto-sums.
A3: Date | B3: Chase Credit Card | C3: Citi Credit Card | D3: Amex Credit Card | E3: Car Loan | F3: Personal Loan | G3: Other Debt | H3: Total Debts
H4: =SUM(B4:G4) -> 0
H5: =SUM(B5:G5) -> 0
H6: =SUM(B6:G6) -> 0
H7: =SUM(B7:G7) -> 0
H8: =SUM(B8:G8) -> 0
H9: =SUM(B9:G9) -> 0
H10: =SUM(B10:G10) -> 0
H11: =SUM(B11:G11) -> 0
H12: =SUM(B12:G12) -> 0
H13: =SUM(B13:G13) -> 0

Sheet Ledger
A1: 🔍 Search / Filter: | D1: Type any keyword, name, or type — matching rows highlight yellow. Leave blank to show all rows.
A2: =IF(C1="","All entries shown",COUNTIF(D6:D205,"*"&C1&"*")+COUNTIF(E6:E205,"*"&C1&"*")+COUNTIF(B6:B205,"*"&C1&"*")&" matching rows highlighted") -> All entries shown
A3: ZAKAT & SADAQAH LEDGER
A4: Record every payment — Zakat, Sadaqah, Fitrana, Qurbani, etc. Amount + Fees = Total Paid. Use the dropdowns for Type, Service, and Given To.
A5: Date | B5: Type | C5: Service Used | D5: Given To | E5: Details / Notes | F5: Amount ($) | G5: Fees ($) | H5: Total Paid ($) | I5: Running Total ($)
H6: =IF(F6+G6=0,"",F6+G6) | I6: =IF(H6="","",H6)
H7: =IF(F7+G7=0,"",F7+G7) | I7: =IF(H7="","",IF(I6="",H7,I6+H7))
H8: =IF(F8+G8=0,"",F8+G8) | I8: =IF(H8="","",IF(I7="",H8,I7+H8))
H9: =IF(F9+G9=0,"",F9+G9) | I9: =IF(H9="","",IF(I8="",H9,I8+H9))
H10: =IF(F10+G10=0,"",F10+G10) | I10: =IF(H10="","",IF(I9="",H10,I9+H10))
H11: =IF(F11+G11=0,"",F11+G11) | I11: =IF(H11="","",IF(I10="",H11,I10+H11))
H12: =IF(F12+G12=0,"",F12+G12) | I12: =IF(H12="","",IF(I11="",H12,I11+H12))
H13: =IF(F13+G13=0,"",F13+G13) | I13: =IF(H13="","",IF(I12="",H13,I12+H13))
H14: =IF(F14+G14=0,"",F14+G14) | I14: =IF(H14="","",IF(I13="",H14,I13+H14))
H15: =IF(F15+G15=0,"",F15+G15) | I15: =IF(H15="","",IF(I14="",H15,I14+H15))
H16: =IF(F16+G16=0,"",F16+G16) | I16: =IF(H16="","",IF(I15="",H16,I15+H16))
H17: =IF(F17+G17=0,"",F17+G17) | I17: =IF(H17="","",IF(I16="",H17,I16+H17))
H18: =IF(F18+G18=0,"",F18+G18) | I18: =IF(H18="","",IF(I17="",H18,I17+H18))
... H205: =IF(F205+G205=0,"",F205+G205) | I205: =IF(H205="","",IF(I204="",H205,I204+H205))

Sheet Reports
A1: Zakat-LogBook v3.0 — PERSON REPORT
A2: Select a person from the dropdown in C4. Use the year filter in C5 to narrow results. All cards and the transaction table update automatically.
K3: Unique Names
A4: Select Person: | D4: Total Given: | F4: =IF($C$4="","—",IF($C$5="All Years",SUMIF(Ledger!$D$6:$D$205,$C$4,Ledger!$H$6:$H$205),SUMPRODUCT((Ledger!$D$6:$D$205=$C$4)*(YEAR(Ledger!$A$6:$A$205)=VALUE($C$5))*Ledger!$H$6:$H$205))) -> — | H4: # Transactions: | I4: =IF($C$4="","—",IF($C$5="All Years",COUNTIF(Ledger!$D$6:$D$205,$C$4),SUMPRODUCT((Ledger!$D$6:$D$205=$C$4)*(YEAR(Ledger!$A$6:$A$205)=VALUE($C$5))))) -> — | K4: =IFERROR(INDEX(Ledger!$D$6:$D$205,MATCH(0,COUNTIF($K$3:K3,Ledger!$D$6:$D$205),0)),"")
A5: Filter by Year: | C5: All Years | D5: Select a year to filter, or leave as 'All Years' | K5: =IFERROR(INDEX(Ledger!$D$6:$D$205,MATCH(0,COUNTIF($K$3:K4,Ledger!$D$6:$D$205),0)),"") | M5: All Years
A6: BREAKDOWN BY TYPE (add types in Settings → Payment Types to extend this table) | K6: =IFERROR(INDEX(Ledger!$D$6:$D$205,MATCH(0,COUNTIF($K$3:K5,Ledger!$D$6:$D$205),0)),"")
A7: Type | F7: Total Paid to Selected Person (Amount + Fees) | K7: =IFERROR(INDEX(Ledger!$D$6:$D$205,MATCH(0,COUNTIF($K$3:K6,Ledger!$D$6:$D$205),0)),"")
A8: =IF(Settings!$B$5="","",Settings!$B$5) -> Zakat | F8: =IF(Settings!$B$5="","",IF($C$4="","—",SUMPRODUCT((Ledger!$D$6:$D$205=$C$4)*(Ledger!$B$6:$B$205=Settings!$B$5)*IF($C$5="All Years",1,YEAR(Ledger!$A$6:$A$205)=IF($C$5="All Years",0,VALUE($C$5)))*Ledger!$H$6:$H$205))) -> — | K8: =IFERROR(INDEX(Ledger!$D$6:$D$205,MATCH(0,COUNTIF($K$3:K7,Ledger!$D$6:$D$205),0)),"")
A9: =IF(Settings!$B$6="","",Settings!$B$6) -> Sadaqah | F9: =IF(Settings!$B$6="","",IF($C$4="","—",SUMPRODUCT((Ledger!$D$6:$D$205=$C$4)*(Ledger!$B$6:$B$205=Settings!$B$6)*IF($C$5="All Years",1,YEAR(Ledger!$A$6:$A$205)=IF($C$5="All Years",0,VALUE($C$5)))*Ledger!$H$6:$H$205))) -> — | K9: =IFERROR(INDEX(Ledger!$D$6:$D$205,MATCH(0,COUNTIF($K$3:K8,Ledger!$D$6:$D$205),0)),"")
A10: =IF(Settings!$B$7="","",Settings!$B$7) -> Fitrana | F10: =IF(Settings!$B$7="","",IF($C$4="","—",SUMPRODUCT((Ledger!$D$6:$D$205=$C$4)*(Ledger!$B$6:$B$205=Settings!$B$7)*IF($C$5="All Years",1,YEAR(Ledger!$A$6:$A$205)=IF($C$5="All Years",0,VALUE($C$5)))*Ledger!$H$6:$H$205))) -> — | K10: =IFERROR(INDEX(Ledger!$D$6:$D$205,MATCH(0,COUNTIF($K$3:K9,Ledger!$D$6:$D$205),0)),"")
A11: =IF(Settings!$B$8="","",Settings!$B$8) -> Qurbani | F11: =IF(Settings!$B$8="","",IF($C$4="","—",SUMPRODUCT((Ledger!$D$6:$D$205=$C$4)*(Ledger!$B$6:$B$205=Settings!$B$8)*IF($C$5="All Years",1,YEAR(Ledger!$A$6:$A$205)=IF($C$5="All Years",0,VALUE($C$5)))*Ledger!$H$6:$H$205))) -> — | K11: =IFERROR(INDEX(Ledger!$D$6:$D$205,MATCH(0,COUNTIF($K$3:K10,Ledger!$D$6:$D$205),0)),"")
A12: =IF(Settings!$B$9="","",Settings!$B$9) | F12: =IF(Settings!$B$9="","",IF($C$4="","—",SUMPRODUCT((Ledger!$D$6:$D$205=$C$4)*(Ledger!$B$6:$B$205=Settings!$B$9)*IF($C$5="All Years",1,YEAR(Ledger!$A$6:$A$205)=IF($C$5="All Years",0,VALUE($C$5)))*Ledger!$H$6:$H$205))) | K12: =IFERROR(INDEX(Ledger!$D$6:$D$205,MATCH(0,COUNTIF($K$3:K11,Ledger!$D$6:$D$205),0)),"")
A13: =IF(Settings!$B$10="","",Settings!$B$10) | F13: =IF(Settings!$B$10="","",IF($C$4="","—",SUMPRODUCT((Ledger!$D$6:$D$205=$C$4)*(Ledger!$B$6:$B$205=Settings!$B$10)*IF($C$5="All Years",1,YEAR(Ledger!$A$6:$A$205)=IF($C$5="All Years",0,VALUE($C$5)))*Ledger!$H$6:$H$205))) | K13: =IFERROR(INDEX(Ledger!$D$6:$D$205,MATCH(0,COUNTIF($K$3:K12,Ledger!$D$6:$D$205),0)),"")
A14: =IF(Settings!$B$11="","",Settings!$B$11) | F14: =IF(Settings!$B$11="","",IF($C$4="","—",SUMPRODUCT((Ledger!$D$6:$D$205=$C$4)*(Ledger!$B$6:$B$205=Settings!$B$11)*IF($C$5="All Years",1,YEAR(Ledger!$A$6:$A$205)=IF($C$5="All Years",0,VALUE($C$5)))*Ledger!$H$6:$H$205))) | K14: =IFERROR(INDEX(Ledger!$D$6:$D$205,MATCH(0,COUNTIF($K$3:K13,Ledger!$D$6:$D$205),0)),"")
A15: =IF(Settings!$B$12="","",Settings!$B$12) | F15: =IF(Settings!$B$12="","",IF($C$4="","—",SUMPRODUCT((Ledger!$D$6:$D$205=$C$4)*(Ledger!$B$6:$B$205=Settings!$B$12)*IF($C$5="All Years",1,YEAR(Ledger!$A$6:$A$205)=IF($C$5="All Years",0,VALUE($C$5)))*Ledger!$H$6:$H$205))) | K15: =IFERROR(INDEX(Ledger!$D$6:$D$205,MATCH(0,COUNTIF($K$3:K14,Ledger!$D$6:$D$205),0)),"")
A16: =IF(Settings!$B$13="","",Settings!$B$13) | F16: =IF(Settings!$B$13="","",IF($C$4="","—",SUMPRODUCT((Ledger!$D$6:$D$205=$C$4)*(Ledger!$B$6:$B$205=Settings!$B$13)*IF($C$5="All Years",1,YEAR(Ledger!$A$6:$A$205)=IF($C$5="All Years",0,VALUE($C$5)))*Ledger!$H$6:$H$205))) | K16: =IFERROR(INDEX(Ledger!$D$6:$D$205,MATCH(0,COUNTIF($K$3:K15,Ledger!$D$6:$D$205),0)),"")
A17: =IF(Settings!$B$14="","",Settings!$B$14) | F17: =IF(Settings!$B$14="","",IF($C$4="","—",SUMPRODUCT((Ledger!$D$6:$D$205=$C$4)*(Ledger!$B$6:$B$205=Settings!$B$14)*IF($C$5="All Years",1,YEAR(Ledger!$A$6:$A$205)=IF($C$5="All Years",0,VALUE($C$5)))*Ledger!$H$6:$H$205))) | K17: =IFERROR(INDEX(Ledger!$D$6:$D$205,MATCH(0,COUNTIF($K$3:K16,Ledger!$D$6:$D$205),0)),"")
A18: =IF(Settings!$B$15="","",Settings!$B$15) | F18: =IF(Settings!$B$15="","",IF($C$4="","—",SUMPRODUCT((Ledger!$D$6:$D$205=$C$4)*(Ledger!$B$6:$B$205=Settings!$B$15)*IF($C$5="All Years",1,YEAR(Ledger!$A$6:$A$205)=IF($C$5="All Years",0,VALUE($C$5)))*Ledger!$H$6:$H$205))) | K18: =IFERROR(INDEX(Ledger!$D$6:$D$205,MATCH(0,COUNTIF($K$3:K17,Ledger!$D$6:$D$205),0)),"")
A19: =IF(Settings!$B$16="","",Settings!$B$16) | F19: =IF(Settings!$B$16="","",IF($C$4="","—",SUMPRODUCT((Ledger!$D$6:$D$205=$C$4)*(Ledger!$B$6:$B$205=Settings!$B$16)*IF($C$5="All Years",1,YEAR(Ledger!$A$6:$A$205)=IF($C$5="All Years",0,VALUE($C$5)))*Ledger!$H$6:$H$205))) | K19: =IFERROR(INDEX(Ledger!$D$6:$D$205,MATCH(0,COUNTIF($K$3:K18,Ledger!$D$6:$D$205),0)),"")
A20: =IF(Settings!$B$17="","",Settings!$B$17) | F20: =IF(Settings!$B$17="","",IF($C$4="","—",SUMPRODUCT((Ledger!$D$6:$D$205=$C$4)*(Ledger!$B$6:$B$205=Settings!$B$17)*IF($C$5="All Years",1,YEAR(Ledger!$A$6:$A$205)=IF($C$5="All Years",0,VALUE($C$5)))*Ledger!$H$6:$H$205))) | K20: =IFERROR(INDEX(Ledger!$D$6:$D$205,MATCH(0,COUNTIF($K$3:K19,Ledger!$D$6:$D$205),0)),"")
A21: =IF(Settings!$B$18="","",Settings!$B$18) | F21: =IF(Settings!$B$18="","",IF($C$4="","—",SUMPRODUCT((Ledger!$D$6:$D$205=$C$4)*(Ledger!$B$6:$B$205=Settings!$B$18)*IF($C$5="All Years",1,YEAR(Ledger!$A$6:$A$205)=IF($C$5="All Years",0,VALUE($C$5)))*Ledger!$H$6:$H$205))) | K21: =IFERROR(INDEX(Ledger!$D$6:$D$205,MATCH(0,COUNTIF($K$3:K20,Ledger!$D$6:$D$205),0)),"")
A22: =IF(Settings!$B$19="","",Settings!$B$19) | F22: =IF(Settings!$B$19="","",IF($C$4="","—",SUMPRODUCT((Ledger!$D$6:$D$205=$C$4)*(Ledger!$B$6:$B$205=Settings!$B$19)*IF($C$5="All Years",1,YEAR(Ledger!$A$6:$A$205)=IF($C$5="All Years",0,VALUE($C$5)))*Ledger!$H$6:$H$205))) | K22: =IFERROR(INDEX(Ledger!$D$6:$D$205,MATCH(0,COUNTIF($K$3:K21,Ledger!$D$6:$D$205),0)),"")
A23: =IF(Settings!$B$20="","",Settings!$B$20) | F23: =IF(Settings!$B$20="","",IF($C$4="","—",SUMPRODUCT((Ledger!$D$6:$D$205=$C$4)*(Ledger!$B$6:$B$205=Settings!$B$20)*IF($C$5="All Years",1,YEAR(Ledger!$A$6:$A$205)=IF($C$5="All Years",0,VALUE($C$5)))*Ledger!$H$6:$H$205))) | K23: =IFERROR(INDEX(Ledger!$D$6:$D$205,MATCH(0,COUNTIF($K$3:K22,Ledger!$D$6:$D$205),0)),"")
A24: =IF(Settings!$B$21="","",Settings!$B$21) | F24: =IF(Settings!$B$21="","",IF($C$4="","—",SUMPRODUCT((Ledger!$D$6:$D$205=$C$4)*(Ledger!$B$6:$B$205=Settings!$B$21)*IF($C$5="All Years",1,YEAR(Ledger!$A$6:$A$205)=IF($C$5="All Years",0,VALUE($C$5)))*Ledger!$H$6:$H$205))) | K24: =IFERROR(INDEX(Ledger!$D$6:$D$205,MATCH(0,COUNTIF($K$3:K23,Ledger!$D$6:$D$205),0)),"")
A25: =IF(Settings!$B$22="","",Settings!$B$22) | F25: =IF(Settings!$B$22="","",IF($C$4="","—",SUMPRODUCT((Ledger!$D$6:$D$205=$C$4)*(Ledger!$B$6:$B$205=Settings!$B$22)*IF($C$5="All Years",1,YEAR(Ledger!$A$6:$A$205)=IF($C$5="All Years",0,VALUE($C$5)))*Ledger!$H$6:$H$205))) | K25: =IFERROR(INDEX(Ledger!$D$6:$D$205,MATCH(0,COUNTIF($K$3:K24,Ledger!$D$6:$D$205),0)),"")
A26: =IF(Settings!$B$23="","",Settings!$B$23) | F26: =IF(Settings!$B$23="","",IF($C$4="","—",SUMPRODUCT((Ledger!$D$6:$D$205=$C$4)*(Ledger!$B$6:$B$205=Settings!$B$23)*IF($C$5="All Years",1,YEAR(Ledger!$A$6:$A$205)=IF($C$5="All Years",0,VALUE($C$5)))*Ledger!$H$6:$H$205))) | K26: =IFERROR(INDEX(Ledger!$D$6:$D$205,MATCH(0,COUNTIF($K$3:K25,Ledger!$D$6:$D$205),0)),"")
A27: =IF(Settings!$B$24="","",Settings!$B$24) | F27: =IF(Settings!$B$24="","",IF($C$4="","—",SUMPRODUCT((Ledger!$D$6:$D$205=$C$4)*(Ledger!$B$6:$B$205=Settings!$B$24)*IF($C$5="All Years",1,YEAR(Ledger!$A$6:$A$205)=IF($C$5="All Years",0,VALUE($C$5)))*Ledger!$H$6:$H$205))) | K27: =IFERROR(INDEX(Ledger!$D$6:$D$205,MATCH(0,COUNTIF($K$3:K26,Ledger!$D$6:$D$205),0)),"")
A28: =IF(Settings!$B$25="","",Settings!$B$25) | F28: =IF(Settings!$B$25="","",IF($C$4="","—",SUMPRODUCT((Ledger!$D$6:$D$205=$C$4)*(Ledger!$B$6:$B$205=Settings!$B$25)*IF($C$5="All Years",1,YEAR(Ledger!$A$6:$A$205)=IF($C$5="All Years",0,VALUE($C$5)))*Ledger!$H$6:$H$205))) | K28: =IFERROR(INDEX(Ledger!$D$6:$D$205,MATCH(0,COUNTIF($K$3:K27,Ledger!$D$6:$D$205),0)),"")
A29: =IF(Settings!$B$26="","",Settings!$B$26) | F29: =IF(Settings!$B$26="","",IF($C$4="","—",SUMPRODUCT((Ledger!$D$6:$D$205=$C$4)*(Ledger!$B$6:$B$205=Settings!$B$26)*IF($C$5="All Years",1,YEAR(Ledger!$A$6:$A$205)=IF($C$5="All Years",0,VALUE($C$5)))*Ledger!$H$6:$H$205))) | K29: =IFERROR(INDEX(Ledger!$D$6:$D$205,MATCH(0,COUNTIF($K$3:K28,Ledger!$D$6:$D$205),0)),"")
A30: =IF(Settings!$B$27="","",Settings!$B$27) | F30: =IF(Settings!$B$27="","",IF($C$4="","—",SUMPRODUCT((Ledger!$D$6:$D$205=$C$4)*(Ledger!$B$6:$B$205=Settings!$B$27)*IF($C$5="All Years",1,YEAR(Ledger!$A$6:$A$205)=IF($C$5="All Years",0,VALUE($C$5)))*Ledger!$H$6:$H$205))) | K30: =IFERROR(INDEX(Ledger!$D$6:$D$205,MATCH(0,COUNTIF($K$3:K29,Ledger!$D$6:$D$205),0)),"")
A31: =IF(Settings!$B$28="","",Settings!$B$28) | F31: =IF(Settings!$B$28="","",IF($C$4="","—",SUMPRODUCT((Ledger!$D$6:$D$205=$C$4)*(Ledger!$B$6:$B$205=Settings!$B$28)*IF($C$5="All Years",1,YEAR(Ledger!$A$6:$A$205)=IF($C$5="All Years",0,VALUE($C$5)))*Ledger!$H$6:$H$205))) | K31: =IFERROR(INDEX(Ledger!$D$6:$D$205,MATCH(0,COUNTIF($K$3:K30,Ledger!$D$6:$D$205),0)),"")
A32: =IF(Settings!$B$29="","",Settings!$B$29) | F32: =IF(Settings!$B$29="","",IF($C$4="","—",SUMPRODUCT((Ledger!$D$6:$D$205=$C$4)*(Ledger!$B$6:$B$205=Settings!$B$29)*IF($C$5="All Years",1,YEAR(Ledger!$A$6:$A$205)=IF($C$5="All Years",0,VALUE($C$5)))*Ledger!$H$6:$H$205))) | K32: =IFERROR(INDEX(Ledger!$D$6:$D$205,MATCH(0,COUNTIF($K$3:K31,Ledger!$D$6:$D$205),0)),"")
A33: =IF(Settings!$B$30="","",Settings!$B$30) | F33: =IF(Settings!$B$30="","",IF($C$4="","—",SUMPRODUCT((Ledger!$D$6:$D$205=$C$4)*(Ledger!$B$6:$B$205=Settings!$B$30)*IF($C$5="All Years",1,YEAR(Ledger!$A$6:$A$205)=IF($C$5="All Years",0,VALUE($C$5)))*Ledger!$H$6:$H$205))) | K33: =IFERROR(INDEX(Ledger!$D$6:$D$205,MATCH(0,COUNTIF($K$3:K32,Ledger!$D$6:$D$205),0)),"")
A34: =IF(Settings!$B$31="","",Settings!$B$31) | F34: =IF(Settings!$B$31="","",IF($C$4="","—",SUMPRODUCT((Ledger!$D$6:$D$205=$C$4)*(Ledger!$B$6:$B$205=Settings!$B$31)*IF($C$5="All Years",1,YEAR(Ledger!$A$6:$A$205)=IF($C$5="All Years",0,VALUE($C$5)))*Ledger!$H$6:$H$205))) | K34: =IFERROR(INDEX(Ledger!$D$6:$D$205,MATCH(0,COUNTIF($K$3:K33,Ledger!$D$6:$D$205),0)),"")
A35: =IF(Settings!$B$32="","",Settings!$B$32) | F35: =IF(Settings!$B$32="","",IF($C$4="","—",SUMPRODUCT((Ledger!$D$6:$D$205=$C$4)*(Ledger!$B$6:$B$205=Settings!$B$32)*IF($C$5="All Years",1,YEAR(Ledger!$A$6:$A$205)=IF($C$5="All Years",0,VALUE($C$5)))*Ledger!$H$6:$H$205))) | K35: =IFERROR(INDEX(Ledger!$D$6:$D$205,MATCH(0,COUNTIF($K$3:K34,Ledger!$D$6:$D$205),0)),"")
A36: =IF(Settings!$B$33="","",Settings!$B$33) | F36: =IF(Settings!$B$33="","",IF($C$4="","—",SUMPRODUCT((Ledger!$D$6:$D$205=$C$4)*(Ledger!$B$6:$B$205=Settings!$B$33)*IF($C$5="All Years",1,YEAR(Ledger!$A$6:$A$205)=IF($C$5="All Years",0,VALUE($C$5)))*Ledger!$H$6:$H$205))) | K36: =IFERROR(INDEX(Ledger!$D$6:$D$205,MATCH(0,COUNTIF($K$3:K35,Ledger!$D$6:$D$205),0)),"")
A37: =IF(Settings!$B$34="","",Settings!$B$34) | F37: =IF(Settings!$B$34="","",IF($C$4="","—",SUMPRODUCT((Ledger!$D$6:$D$205=$C$4)*(Ledger!$B$6:$B$205=Settings!$B$34)*IF($C$5="All Years",1,YEAR(Ledger!$A$6:$A$205)=IF($C$5="All Years",0,VALUE($C$5)))*Ledger!$H$6:$H$205))) | K37: =IFERROR(INDEX(Ledger!$D$6:$D$205,MATCH(0,COUNTIF($K$3:K36,Ledger!$D$6:$D$205),0)),"")
K38: =IFERROR(INDEX(Ledger!$D$6:$D$205,MATCH(0,COUNTIF($K$3:K37,Ledger!$D$6:$D$205),0)),"")
A39: TOTAL (all types) | F39: =IF($C$4="","—",SUMPRODUCT((Ledger!$D$6:$D$205=$C$4)*IF($C$5="All Years",1,YEAR(Ledger!$A$6:$A$205)=IF($C$5="All Years",0,VALUE($C$5)))*Ledger!$H$6:$H$205)) -> — | K39: =IFERROR(INDEX(Ledger!$D$6:$D$205,MATCH(0,COUNTIF($K$3:K38,Ledger!$D$6:$D$205),0)),"")
K40: =IFERROR(INDEX(Ledger!$D$6:$D$205,MATCH(0,COUNTIF($K$3:K39,Ledger!$D$6:$D$205),0)),"")
...
